<?xml version="1.0" ?>
<!-- Generated using onshape-to-robot -->
<!-- Onshape https://cad.onshape.com/documents/6006520d7e567b7f616afa69/w/f5d6c01614216363a8f5deb8/e/0e8fe2c78e38de67c452e429 -->
<mujoco model="leggy">
  <compiler angle="radian" meshdir="assets" autolimits="true"/>
  <default>
    <default class="leggy">
      <joint frictionloss="0.1" armature="0.005"/>
      <position kp="50" dampratio="1"/>
      <default class="visual">
        <geom type="mesh" contype="0" conaffinity="0" group="2"/>
      </default>
      <default class="collision">
        <geom group="3"/>
      </default>
    </default>
  </default>
  <!-- Additional sensors.xml -->
  <sensor>
    <framequat name="orientation" objtype="site" noise="0.001" objname="imu"/>
    <gyro name="imu_ang_vel" site="imu"/>
    <velocimeter name="imu_lin_vel" site="imu"/>
    <subtreeangmom name="root_angmom" body="boddy"/>
  </sensor>
  <worldbody>
    <!-- Link boddy -->
    <body name="boddy" pos="0 0 0" quat="1 0 0 0" childclass="leggy">
      <freejoint name="boddy_freejoint"/>
      <inertial pos="-0.014209 -2.19223e-06 0.00921744" mass="0.227015" fullinertia="0.00030365 0.000271492 0.000253797 -1.3678e-08 9.36271e-05 5.205e-09"/>
      <!-- Part trunclink -->
      <geom class="visual" type="mesh" pos="-0.0033 4.9559e-12 0.0157128" quat="1 -4.88032e-16 2.97923e-16 1.55715e-14" mesh="trunclink" material="trunclink_material"/>
      <!-- Part antenna -->
      <geom class="visual" type="mesh" pos="-0.0677 0.0162429 0.0172174" quat="0.999048 -0.0436194 -4.3627e-16 1.57857e-14" mesh="antenna" material="antenna_material"/>
      <!-- Part brd -->
      <geom class="visual" type="mesh" pos="-0.0033 4.95596e-12 0.0157128" quat="1 -5.34438e-16 -2.57203e-15 1.57123e-14" mesh="brd" material="brd_material"/>
      <!-- Part antenna_2 -->
      <geom class="visual" type="mesh" pos="-0.0677 -0.0162429 0.0172174" quat="0.999048 0.0436194 8.82472e-16 1.57633e-14" mesh="antenna" material="antenna_material"/>
      <!-- Part cm4lite -->
      <!-- Part intel_ax210_ngw_wifi_6___bt_nvme_parts -->
      <!-- Part gear2__c331c3826e3aeff78bc4513233f2bf84 -->
      <geom class="visual" type="mesh" pos="-0.0053 -0.0216385 -0.0312708" quat="0.949415 -0.314023 -4.42706e-15 1.55025e-14" mesh="gear2__c331c3826e3aeff78bc4513233f2bf84" material="gear2__c331c3826e3aeff78bc4513233f2bf84_material"/>
      <!-- Part mr63 -->
      <geom class="visual" type="mesh" pos="0.0033 -0.01855 -0.000874538" quat="0.317696 -0.631719 0.317696 -0.631719" mesh="mr63" material="mr63_material"/>
      <!-- Part spacer_small__c331c3826e3aeff78bc4513233f2bf84 -->
      <geom class="visual" type="mesh" pos="-0.0077 -0.026289 -0.0221374" quat="1.42288e-14 -4.73508e-15 0.21644 -0.976296" mesh="spacer_small__c331c3826e3aeff78bc4513233f2bf84" material="spacer_small__c331c3826e3aeff78bc4513233f2bf84_material"/>
      <!-- Part enc_magnet -->
      <geom class="visual" type="mesh" pos="0.0055 -0.0389902 0.000689504" quat="0.347156 0.616021 -0.347156 -0.616021" mesh="enc_magnet" material="enc_magnet_material"/>
      <!-- Part rotor -->
      <geom class="visual" type="mesh" pos="-0.0238 -0.01855 -0.000874538" quat="1.27858e-14 -7.72293e-15 0.449291 -0.893386" mesh="rotor" material="rotor_material"/>
      <!-- Part output_axis__c331c3826e3aeff78bc4513233f2bf84 -->
      <geom class="visual" type="mesh" pos="-0.0053 -0.0568447 0.0107627" quat="0.490953 0.871186 9.37516e-15 1.00712e-14" mesh="output_axis__c331c3826e3aeff78bc4513233f2bf84" material="output_axis__c331c3826e3aeff78bc4513233f2bf84_material"/>
      <!-- Part mr63_2 -->
      <geom class="visual" type="mesh" pos="-0.0033 -0.0389902 0.000689504" quat="0.235665 -0.66668 -0.235665 0.66668" mesh="mr63" material="mr63_material"/>
      <!-- Part gear3__c331c3826e3aeff78bc4513233f2bf84 -->
      <geom class="visual" type="mesh" pos="-0.0053 -0.0568447 0.0107627" quat="0.490953 0.871186 1.42273e-14 7.41281e-15" mesh="gear3__c331c3826e3aeff78bc4513233f2bf84" material="gear3__c331c3826e3aeff78bc4513233f2bf84_material"/>
      <!-- Part short_axe__c331c3826e3aeff78bc4513233f2bf84 -->
      <geom class="visual" type="mesh" pos="-0.0053 -0.0285876 -0.0152097" quat="0.449291 -0.893386 -1.40665e-14 7.8414e-15" mesh="short_axe__c331c3826e3aeff78bc4513233f2bf84" material="short_axe__c331c3826e3aeff78bc4513233f2bf84_material"/>
      <!-- Part spacer_small__c331c3826e3aeff78bc4513233f2bf84_2 -->
      <geom class="visual" type="mesh" pos="-0.0077 -0.01855 -0.000874538" quat="1.41694e-14 -4.11051e-15 0.21644 -0.976296" mesh="spacer_small__c331c3826e3aeff78bc4513233f2bf84" material="spacer_small__c331c3826e3aeff78bc4513233f2bf84_material"/>
      <!-- Part pcb_support__c331c3826e3aeff78bc4513233f2bf84 -->
      <geom class="visual" type="mesh" pos="0.0139 -0.01855 -0.000874538" quat="4.15072e-15 1.55645e-14 -0.976296 -0.21644" mesh="pcb_support__c331c3826e3aeff78bc4513233f2bf84" material="pcb_support__c331c3826e3aeff78bc4513233f2bf84_material"/>
      <!-- Part spacer_small__c331c3826e3aeff78bc4513233f2bf84_3 -->
      <geom class="visual" type="mesh" pos="-0.0077 0.00271282 -0.00861357" quat="1.41284e-14 -4.09367e-15 0.21644 -0.976296" mesh="spacer_small__c331c3826e3aeff78bc4513233f2bf84" material="spacer_small__c331c3826e3aeff78bc4513233f2bf84_material"/>
      <!-- Part spacer__c331c3826e3aeff78bc4513233f2bf84 -->
      <geom class="visual" type="mesh" pos="0.0053 -0.00502622 -0.0298764" quat="1.50148e-14 -4.88549e-15 0.21644 -0.976296" mesh="spacer__c331c3826e3aeff78bc4513233f2bf84" material="spacer__c331c3826e3aeff78bc4513233f2bf84_material"/>
      <!-- Part stator -->
      <geom class="visual" type="mesh" pos="-0.0238 -0.01855 -0.000874538" quat="4.01745e-15 1.41448e-14 -0.976296 -0.21644" mesh="stator" material="stator_material"/>
      <!-- Part output_support__c331c3826e3aeff78bc4513233f2bf84 -->
      <geom class="visual" type="mesh" pos="-0.0121 -0.01855 -0.000874538" quat="4.64771e-15 1.43069e-14 -0.976296 -0.21644" mesh="output_support__c331c3826e3aeff78bc4513233f2bf84" material="output_support__c331c3826e3aeff78bc4513233f2bf84_material"/>
      <!-- Part gear1__c331c3826e3aeff78bc4513233f2bf84 -->
      <geom class="visual" type="mesh" pos="0.0021 -0.01855 -0.000874538" quat="1.48515e-14 -8.42818e-15 0.449291 -0.893386" mesh="gear1__c331c3826e3aeff78bc4513233f2bf84" material="gear1__c331c3826e3aeff78bc4513233f2bf84_material"/>
      <!-- Part mr63_3 -->
      <geom class="visual" type="mesh" pos="-0.0097 -0.0389902 0.000689504" quat="0.551588 0.442437 0.551588 0.442437" mesh="mr63" material="mr63_material"/>
      <!-- Part short_axe__c331c3826e3aeff78bc4513233f2bf84_2 -->
      <geom class="visual" type="mesh" pos="0.0053 -0.01855 -0.000874538" quat="1.47693e-14 -8.48524e-15 0.449291 -0.893386" mesh="short_axe__c331c3826e3aeff78bc4513233f2bf84" material="short_axe__c331c3826e3aeff78bc4513233f2bf84_material"/>
      <!-- Part mr63_4 -->
      <geom class="visual" type="mesh" pos="0.0033 -0.0389902 0.000689504" quat="0.48148 -0.517858 0.48148 -0.517858" mesh="mr63" material="mr63_material"/>
      <!-- Part enc_magnet_2 -->
      <geom class="visual" type="mesh" pos="-0.0099 -0.0389902 0.000689504" quat="0.347156 0.616021 0.347156 0.616021" mesh="enc_magnet" material="enc_magnet_material"/>
      <!-- Part motor_support__c331c3826e3aeff78bc4513233f2bf84 -->
      <geom class="visual" type="mesh" pos="-0.0033 -0.01855 -0.000874538" quat="4.34559e-15 1.42128e-14 -0.976296 -0.21644" mesh="motor_support__c331c3826e3aeff78bc4513233f2bf84" material="motor_support__c331c3826e3aeff78bc4513233f2bf84_material"/>
      <!-- Part spring__c331c3826e3aeff78bc4513233f2bf84 -->
      <geom class="visual" type="mesh" pos="0.0037 -0.0396406 0.0211792" quat="1.01226e-14 5.94858e-15 -0.490953 -0.871186" mesh="spring__c331c3826e3aeff78bc4513233f2bf84" material="spring__c331c3826e3aeff78bc4513233f2bf84_material"/>
      <!-- Part spacer__c331c3826e3aeff78bc4513233f2bf84_2 -->
      <geom class="visual" type="mesh" pos="0.0053 -0.01855 -0.000874538" quat="2.50008e-14 -5.79217e-14 0.21644 -0.976296" mesh="spacer__c331c3826e3aeff78bc4513233f2bf84" material="spacer__c331c3826e3aeff78bc4513233f2bf84_material"/>
      <!-- Part gear2__c331c3826e3aeff78bc4513233f2bf84_2 -->
      <geom class="visual" type="mesh" pos="-0.0053 0.0356517 -0.0312206" quat="0.950536 -0.310614 -4.64335e-15 1.47317e-14" mesh="gear2__c331c3826e3aeff78bc4513233f2bf84" material="gear2__c331c3826e3aeff78bc4513233f2bf84_material"/>
      <!-- Part mr63_5 -->
      <geom class="visual" type="mesh" pos="0.0033 0.01855 -0.000874538" quat="0.153046 0.690346 0.153046 0.690346" mesh="mr63" material="mr63_material"/>
      <!-- Part spacer_small__c331c3826e3aeff78bc4513233f2bf84_4 -->
      <geom class="visual" type="mesh" pos="-0.0077 -0.00271282 -0.00861357" quat="1.55205e-14 3.76387e-15 -0.21644 -0.976296" mesh="spacer_small__c331c3826e3aeff78bc4513233f2bf84" material="spacer_small__c331c3826e3aeff78bc4513233f2bf84_material"/>
      <!-- Part enc_magnet_3 -->
      <geom class="visual" type="mesh" pos="0.0055 0.0389902 0.000689504" quat="0.611699 -0.354717 -0.611699 0.354717" mesh="enc_magnet" material="enc_magnet_material"/>
      <!-- Part rotor_2 -->
      <geom class="visual" type="mesh" pos="-0.0238 0.01855 -0.000874538" quat="1.44871e-14 -8.08921e-15 0.452494 -0.891768" mesh="rotor" material="rotor_material"/>
      <!-- Part output_axis__c331c3826e3aeff78bc4513233f2bf84_2 -->
      <geom class="visual" type="mesh" pos="-0.0053 0.0565912 -0.00982035" quat="0.865073 -0.501645 -7.65344e-15 1.40536e-14" mesh="output_axis__c331c3826e3aeff78bc4513233f2bf84" material="output_axis__c331c3826e3aeff78bc4513233f2bf84_material"/>
      <!-- Part mr63_6 -->
      <geom class="visual" type="mesh" pos="-0.0033 0.0389902 0.000689504" quat="0.153046 0.690346 -0.153046 -0.690346" mesh="mr63" material="mr63_material"/>
      <!-- Part gear3__c331c3826e3aeff78bc4513233f2bf84_2 -->
      <geom class="visual" type="mesh" pos="-0.0053 0.0565912 -0.00982035" quat="0.865073 -0.501645 -7.68339e-15 1.33674e-14" mesh="gear3__c331c3826e3aeff78bc4513233f2bf84" material="gear3__c331c3826e3aeff78bc4513233f2bf84_material"/>
      <!-- Part short_axe__c331c3826e3aeff78bc4513233f2bf84_3 -->
      <geom class="visual" type="mesh" pos="-0.0053 0.0285876 -0.0152097" quat="0.21644 0.976296 1.27411e-14 3.26034e-15" mesh="short_axe__c331c3826e3aeff78bc4513233f2bf84" material="short_axe__c331c3826e3aeff78bc4513233f2bf84_material"/>
      <!-- Part spacer_small__c331c3826e3aeff78bc4513233f2bf84_5 -->
      <geom class="visual" type="mesh" pos="-0.0077 0.01855 -0.000874538" quat="1.6033e-14 3.10297e-15 -0.21644 -0.976296" mesh="spacer_small__c331c3826e3aeff78bc4513233f2bf84" material="spacer_small__c331c3826e3aeff78bc4513233f2bf84_material"/>
      <!-- Part pcb_support__c331c3826e3aeff78bc4513233f2bf84_2 -->
      <geom class="visual" type="mesh" pos="-0.0053 0.01855 -0.000874538" quat="0.21644 0.976296 1.50425e-14 3.25687e-15" mesh="pcb_support__c331c3826e3aeff78bc4513233f2bf84" material="pcb_support__c331c3826e3aeff78bc4513233f2bf84_material"/>
      <!-- Part spacer_small__c331c3826e3aeff78bc4513233f2bf84_6 -->
      <geom class="visual" type="mesh" pos="-0.0077 0.026289 -0.0221374" quat="1.6033e-14 3.10297e-15 -0.21644 -0.976296" mesh="spacer_small__c331c3826e3aeff78bc4513233f2bf84" material="spacer_small__c331c3826e3aeff78bc4513233f2bf84_material"/>
      <!-- Part spacer__c331c3826e3aeff78bc4513233f2bf84_3 -->
      <geom class="visual" type="mesh" pos="0.0053 0.00502622 -0.0298764" quat="1.56124e-14 2.73286e-15 -0.21644 -0.976296" mesh="spacer__c331c3826e3aeff78bc4513233f2bf84" material="spacer__c331c3826e3aeff78bc4513233f2bf84_material"/>
      <!-- Part stator_2 -->
      <geom class="visual" type="mesh" pos="-0.0238 0.01855 -0.000874538" quat="3.7031e-15 -1.56871e-14 0.976296 -0.21644" mesh="stator" material="stator_material"/>
      <!-- Part output_support__c331c3826e3aeff78bc4513233f2bf84_2 -->
      <geom class="visual" type="mesh" pos="-0.0053 0.01855 -0.000874538" quat="0.21644 0.976296 1.54974e-14 3.72784e-15" mesh="output_support__c331c3826e3aeff78bc4513233f2bf84" material="output_support__c331c3826e3aeff78bc4513233f2bf84_material"/>
      <!-- Part gear1__c331c3826e3aeff78bc4513233f2bf84_2 -->
      <geom class="visual" type="mesh" pos="0.0021 0.01855 -0.000874538" quat="2.47476e-15 1.51923e-14 -0.987829 -0.155545" mesh="gear1__c331c3826e3aeff78bc4513233f2bf84" material="gear1__c331c3826e3aeff78bc4513233f2bf84_material"/>
      <!-- Part mr63_7 -->
      <geom class="visual" type="mesh" pos="-0.0097 0.0389902 0.000689504" quat="0.153046 0.690346 0.153046 0.690346" mesh="mr63" material="mr63_material"/>
      <!-- Part short_axe__c331c3826e3aeff78bc4513233f2bf84_4 -->
      <geom class="visual" type="mesh" pos="0.0053 0.01855 -0.000874538" quat="1.52542e-14 -1.9787e-15 0.155545 -0.987829" mesh="short_axe__c331c3826e3aeff78bc4513233f2bf84" material="short_axe__c331c3826e3aeff78bc4513233f2bf84_material"/>
      <!-- Part mr63_8 -->
      <geom class="visual" type="mesh" pos="0.0033 0.0389902 0.000689504" quat="0.153046 0.690346 0.153046 0.690346" mesh="mr63" material="mr63_material"/>
      <!-- Part enc_magnet_4 -->
      <geom class="visual" type="mesh" pos="-0.0099 0.0389902 0.000689504" quat="0.611699 -0.354717 0.611699 -0.354717" mesh="enc_magnet" material="enc_magnet_material"/>
      <!-- Part motor_support__c331c3826e3aeff78bc4513233f2bf84_2 -->
      <geom class="visual" type="mesh" pos="-0.0053 0.01855 -0.000874538" quat="0.21644 0.976296 1.44327e-14 3.48646e-15" mesh="motor_support__c331c3826e3aeff78bc4513233f2bf84" material="motor_support__c331c3826e3aeff78bc4513233f2bf84_material"/>
      <!-- Part spring__c331c3826e3aeff78bc4513233f2bf84_2 -->
      <geom class="visual" type="mesh" pos="0.0037 0.0391357 -0.01981" quat="7.51351e-15 -1.34166e-14 0.865073 -0.501645" mesh="spring__c331c3826e3aeff78bc4513233f2bf84" material="spring__c331c3826e3aeff78bc4513233f2bf84_material"/>
      <!-- Part spacer__c331c3826e3aeff78bc4513233f2bf84_4 -->
      <geom class="visual" type="mesh" pos="0.0053 0.01855 -0.000874538" quat="1.55212e-14 3.57274e-15 -0.21644 -0.976296" mesh="spacer__c331c3826e3aeff78bc4513233f2bf84" material="spacer__c331c3826e3aeff78bc4513233f2bf84_material"/>
      <!-- Frame imu -->
      <site group="3" name="imu" pos="-0.0218553 -1.02128e-05 0.0216755" quat="1 -0 -0 0"/>
      <!-- Link lhip -->
      <body name="lhip" pos="-0.0077 0.0389902 0.000689504" quat="0.596368 0.379928 -0.596368 -0.379928">
        <!-- Joint from boddy to lhip -->
        <joint axis="0 0 1" name="LhipY" type="hinge" range="-1.57 1.57" frictionloss="0.01" armature="6.499e-05" damping="0.008824"/>
        <inertial pos="-0.00748013 -0.0096728 0.0402115" mass="0.161992" fullinertia="4.30951e-05 7.45436e-05 6.13064e-05 -1.52593e-05 1.1318e-05 3.7243e-06"/>
        <!-- Part output__c331c3826e3aeff78bc4513233f2bf84 -->
        <geom class="visual" type="mesh" pos="0.0178642 -0.0100559 -0.0024" quat="0.5 0.5 0.5 -0.5" mesh="output__c331c3826e3aeff78bc4513233f2bf84" material="output__c331c3826e3aeff78bc4513233f2bf84_material"/>
        <!-- Part kneelinkl -->
        <geom class="visual" type="mesh" pos="-0.0245159 -0.0207981 0.0488876" quat="0.755855 0.244052 -0.436393 0.42271" mesh="kneelinkl" material="kneelinkl_material"/>
        <!-- Part gear2__c331c3826e3aeff78bc4513233f2bf84_3 -->
        <geom class="visual" type="mesh" pos="0.0209738 0.0146513 0.0554303" quat="0.00659886 0.271932 0.962011 0.0233447" mesh="gear2__c331c3826e3aeff78bc4513233f2bf84" material="gear2__c331c3826e3aeff78bc4513233f2bf84_material"/>
        <!-- Part mr63_9 -->
        <geom class="visual" type="mesh" pos="0.00136323 -0.000837617 0.0308" quat="0.330068 0.360011 -0.608598 -0.625344" mesh="mr63" material="mr63_material"/>
        <!-- Part spacer_small__c331c3826e3aeff78bc4513233f2bf84_7 -->
        <geom class="visual" type="mesh" pos="0.0191116 0.00703607 0.0468" quat="0.680445 0.680445 -0.192341 -0.192341" mesh="spacer_small__c331c3826e3aeff78bc4513233f2bf84" material="spacer_small__c331c3826e3aeff78bc4513233f2bf84_material"/>
        <!-- Part enc_magnet_5 -->
        <geom class="visual" type="mesh" pos="-0.00577559 -0.00825374 0.0486642" quat="0.0906858 -0.550018 0.444387 -0.701267" mesh="enc_magnet" material="enc_magnet_material"/>
        <!-- Part rotor_3 -->
        <geom class="visual" type="mesh" pos="0.024453 -0.0150248 0.0308" quat="0.508982 0.816668 -0.230848 -0.143874" mesh="rotor" material="rotor_material"/>
        <!-- Part output_axis__c331c3826e3aeff78bc4513233f2bf84_3 -->
        <geom class="visual" type="mesh" pos="-0.00684068 -0.0306171 0.0426948" quat="0.250105 -0.106949 -0.378354 0.884793" mesh="output_axis__c331c3826e3aeff78bc4513233f2bf84" material="output_axis__c331c3826e3aeff78bc4513233f2bf84_material"/>
        <!-- Part mr63_10 -->
        <geom class="visual" type="mesh" pos="0.00172217 -0.0128606 0.0486642" quat="0.520067 0.680457 0.192297 0.479093" mesh="mr63" material="mr63_material"/>
        <!-- Part gear3__c331c3826e3aeff78bc4513233f2bf84_3 -->
        <geom class="visual" type="mesh" pos="-0.00684068 -0.0306171 0.0426948" quat="0.250105 -0.106949 -0.378354 0.884793" mesh="gear3__c331c3826e3aeff78bc4513233f2bf84" material="gear3__c331c3826e3aeff78bc4513233f2bf84_material"/>
        <!-- Part short_axe__c331c3826e3aeff78bc4513233f2bf84_5 -->
        <geom class="visual" type="mesh" pos="0.0132713 0.00211536 0.0459554" quat="0.196951 0.187619 0.663737 0.696752" mesh="short_axe__c331c3826e3aeff78bc4513233f2bf84" material="short_axe__c331c3826e3aeff78bc4513233f2bf84_material"/>
        <!-- Part spacer_small__c331c3826e3aeff78bc4513233f2bf84_8 -->
        <geom class="visual" type="mesh" pos="0.0107354 -0.00659623 0.0308" quat="0.680445 0.680445 -0.192341 -0.192341" mesh="spacer_small__c331c3826e3aeff78bc4513233f2bf84" material="spacer_small__c331c3826e3aeff78bc4513233f2bf84_material"/>
        <!-- Part pcb_support__c331c3826e3aeff78bc4513233f2bf84_3 -->
        <geom class="visual" type="mesh" pos="-0.00766817 0.0047116 0.0308" quat="0.680445 -0.680445 0.192341 -0.192341" mesh="pcb_support__c331c3826e3aeff78bc4513233f2bf84" material="pcb_support__c331c3826e3aeff78bc4513233f2bf84_material"/>
        <!-- Part spacer_small__c331c3826e3aeff78bc4513233f2bf84_9 -->
        <geom class="visual" type="mesh" pos="0.0191116 0.00703607 0.0148" quat="0.680445 0.680445 -0.192341 -0.192341" mesh="spacer_small__c331c3826e3aeff78bc4513233f2bf84" material="spacer_small__c331c3826e3aeff78bc4513233f2bf84_material"/>
        <!-- Part spacer__c331c3826e3aeff78bc4513233f2bf84_5 -->
        <geom class="visual" type="mesh" pos="0.0164115 0.027474 0.0308" quat="0.680445 0.680445 -0.192341 -0.192341" mesh="spacer__c331c3826e3aeff78bc4513233f2bf84" material="spacer__c331c3826e3aeff78bc4513233f2bf84_material"/>
        <!-- Part stator_3 -->
        <geom class="visual" type="mesh" pos="0.024453 -0.0150248 0.0308" quat="0.680445 -0.680445 0.192341 -0.192341" mesh="stator" material="stator_material"/>
        <!-- Part output_support__c331c3826e3aeff78bc4513233f2bf84_3 -->
        <geom class="visual" type="mesh" pos="0.0144843 -0.00889968 0.0308" quat="0.680445 -0.680445 0.192341 -0.192341" mesh="output_support__c331c3826e3aeff78bc4513233f2bf84" material="output_support__c331c3826e3aeff78bc4513233f2bf84_material"/>
        <!-- Part gear1__c331c3826e3aeff78bc4513233f2bf84_3 -->
        <geom class="visual" type="mesh" pos="0.00238565 -0.00146583 0.0308" quat="0.663737 0.696752 -0.196951 -0.187619" mesh="gear1__c331c3826e3aeff78bc4513233f2bf84" material="gear1__c331c3826e3aeff78bc4513233f2bf84_material"/>
        <!-- Part mr63_11 -->
        <geom class="visual" type="mesh" pos="0.0071751 -0.0162111 0.0486642" quat="0.0733195 -0.637605 0.305713 0.703295" mesh="mr63" material="mr63_material"/>
        <!-- Part short_axe__c331c3826e3aeff78bc4513233f2bf84_6 -->
        <geom class="visual" type="mesh" pos="-0.000340808 0.000209404 0.0308" quat="0.663737 0.696752 -0.196951 -0.187619" mesh="short_axe__c331c3826e3aeff78bc4513233f2bf84" material="short_axe__c331c3826e3aeff78bc4513233f2bf84_material"/>
        <!-- Part mr63_12 -->
        <geom class="visual" type="mesh" pos="-0.00390115 -0.00940546 0.0486642" quat="0.491578 0.17572 -0.684925 -0.508282" mesh="mr63" material="mr63_material"/>
        <!-- Part enc_magnet_6 -->
        <geom class="visual" type="mesh" pos="0.0073455 -0.0163158 0.0486642" quat="0.444387 -0.701267 -0.0906858 0.550018" mesh="enc_magnet" material="enc_magnet_material"/>
        <!-- Part motor_support__c331c3826e3aeff78bc4513233f2bf84_3 -->
        <geom class="visual" type="mesh" pos="0.00698656 -0.00429279 0.0308" quat="0.680445 -0.680445 0.192341 -0.192341" mesh="motor_support__c331c3826e3aeff78bc4513233f2bf84" material="motor_support__c331c3826e3aeff78bc4513233f2bf84_material"/>
        <!-- Part spring__c331c3826e3aeff78bc4513233f2bf84_3 -->
        <geom class="visual" type="mesh" pos="-0.00689629 -0.013516 0.0288011" quat="0.378354 -0.884793 0.250105 -0.106949" mesh="spring__c331c3826e3aeff78bc4513233f2bf84" material="spring__c331c3826e3aeff78bc4513233f2bf84_material"/>
        <!-- Part spacer__c331c3826e3aeff78bc4513233f2bf84_6 -->
        <geom class="visual" type="mesh" pos="-0.000340808 0.000209404 0.0308" quat="0.680445 0.680445 -0.192341 -0.192341" mesh="spacer__c331c3826e3aeff78bc4513233f2bf84" material="spacer__c331c3826e3aeff78bc4513233f2bf84_material"/>
        <!-- Part gear2__c331c3826e3aeff78bc4513233f2bf84_4 -->
        <geom class="visual" type="mesh" pos="-0.0306573 -0.026973 0.0306488" quat="0.330291 -0.903835 0.255487 -0.0933634" mesh="gear2__c331c3826e3aeff78bc4513233f2bf84" material="gear2__c331c3826e3aeff78bc4513233f2bf84_material"/>
        <!-- Part mr63_13 -->
        <geom class="visual" type="mesh" pos="-0.0188926 -0.0242533 0.0488876" quat="0.3619 0.707041 -0.00967549 0.607477" mesh="mr63" material="mr63_material"/>
        <!-- Part spacer_small__c331c3826e3aeff78bc4513233f2bf84_10 -->
        <geom class="visual" type="mesh" pos="-0.0397068 -0.0371167 0.0430312" quat="0.262743 0.0704018 0.24906 0.929505" mesh="spacer_small__c331c3826e3aeff78bc4513233f2bf84" material="spacer_small__c331c3826e3aeff78bc4513233f2bf84_material"/>
        <!-- Part enc_magnet_7 -->
        <geom class="visual" type="mesh" pos="-0.00628681 -0.00793963 0.0486642" quat="0.678695 -0.18624 -0.68214 -0.198428" mesh="enc_magnet" material="enc_magnet_material"/>
        <!-- Part rotor_4 -->
        <geom class="visual" type="mesh" pos="-0.0419823 -0.0100661 0.0488876" quat="0.114639 -0.246675 -0.872659 0.405557" mesh="rotor" material="rotor_material"/>
        <!-- Part output_axis__c331c3826e3aeff78bc4513233f2bf84_4 -->
        <geom class="visual" type="mesh" pos="-0.00623232 0.012779 0.0590384" quat="0.962255 0.00861806 -0.00243607 -0.272001" mesh="output_axis__c331c3826e3aeff78bc4513233f2bf84" material="output_axis__c331c3826e3aeff78bc4513233f2bf84_material"/>
        <!-- Part mr63_14 -->
        <geom class="visual" type="mesh" pos="-0.0137846 -0.00333274 0.0486642" quat="0.00967549 -0.607477 0.3619 0.707041" mesh="mr63" material="mr63_material"/>
        <!-- Part gear3__c331c3826e3aeff78bc4513233f2bf84_4 -->
        <geom class="visual" type="mesh" pos="-0.00623232 0.012779 0.0590384" quat="0.962255 0.00861806 -0.00243607 -0.272001" mesh="gear3__c331c3826e3aeff78bc4513233f2bf84" material="gear3__c331c3826e3aeff78bc4513233f2bf84_material"/>
        <!-- Part short_axe__c331c3826e3aeff78bc4513233f2bf84_7 -->
        <geom class="visual" type="mesh" pos="-0.0216392 -0.0122959 0.0337321" quat="0.24906 0.929505 -0.262743 -0.0704018" mesh="short_axe__c331c3826e3aeff78bc4513233f2bf84" material="short_axe__c331c3826e3aeff78bc4513233f2bf84_material"/>
        <!-- Part spacer_small__c331c3826e3aeff78bc4513233f2bf84_11 -->
        <geom class="visual" type="mesh" pos="-0.0282648 -0.0184946 0.0488876" quat="0.262743 0.0704018 0.24906 0.929505" mesh="spacer_small__c331c3826e3aeff78bc4513233f2bf84" material="spacer_small__c331c3826e3aeff78bc4513233f2bf84_material"/>
        <!-- Part pcb_support__c331c3826e3aeff78bc4513233f2bf84_4 -->
        <geom class="visual" type="mesh" pos="-0.0262199 -0.0197511 0.0488876" quat="0.24906 0.929505 -0.262743 -0.0704018" mesh="pcb_support__c331c3826e3aeff78bc4513233f2bf84" material="pcb_support__c331c3826e3aeff78bc4513233f2bf84_material"/>
        <!-- Part spacer_small__c331c3826e3aeff78bc4513233f2bf84_12 -->
        <geom class="visual" type="mesh" pos="-0.0251989 -0.0135049 0.0270312" quat="0.262743 0.0704018 0.24906 0.929505" mesh="spacer_small__c331c3826e3aeff78bc4513233f2bf84" material="spacer_small__c331c3826e3aeff78bc4513233f2bf84_material"/>
        <!-- Part spacer__c331c3826e3aeff78bc4513233f2bf84_7 -->
        <geom class="visual" type="mesh" pos="-0.0255647 -0.0389326 0.0211747" quat="0.262743 0.0704018 0.24906 0.929505" mesh="spacer__c331c3826e3aeff78bc4513233f2bf84" material="spacer__c331c3826e3aeff78bc4513233f2bf84_material"/>
        <!-- Part stator_4 -->
        <geom class="visual" type="mesh" pos="-0.0419823 -0.0100661 0.0488876" quat="0.0704018 -0.262743 -0.929505 0.24906" mesh="stator" material="stator_material"/>
        <!-- Part output_support__c331c3826e3aeff78bc4513233f2bf84_4 -->
        <geom class="visual" type="mesh" pos="-0.0262199 -0.0197511 0.0488876" quat="0.24906 0.929505 -0.262743 -0.0704018" mesh="output_support__c331c3826e3aeff78bc4513233f2bf84" material="output_support__c331c3826e3aeff78bc4513233f2bf84_material"/>
        <!-- Part gear1__c331c3826e3aeff78bc4513233f2bf84_4 -->
        <geom class="visual" type="mesh" pos="-0.019915 -0.023625 0.0488876" quat="0.246675 0.114639 0.405557 0.872659" mesh="gear1__c331c3826e3aeff78bc4513233f2bf84" material="gear1__c331c3826e3aeff78bc4513233f2bf84_material"/>
        <!-- Part mr63_15 -->
        <geom class="visual" type="mesh" pos="-0.0192375 1.77317e-05 0.0486642" quat="0.3619 0.707041 -0.00967549 0.607477" mesh="mr63" material="mr63_material"/>
        <!-- Part short_axe__c331c3826e3aeff78bc4513233f2bf84_8 -->
        <geom class="visual" type="mesh" pos="-0.0171885 -0.0253003 0.0488876" quat="0.114639 -0.246675 -0.872659 0.405557" mesh="short_axe__c331c3826e3aeff78bc4513233f2bf84" material="short_axe__c331c3826e3aeff78bc4513233f2bf84_material"/>
        <!-- Part mr63_16 -->
        <geom class="visual" type="mesh" pos="-0.00816125 -0.00678791 0.0486642" quat="0.3619 0.707041 -0.00967549 0.607477" mesh="mr63" material="mr63_material"/>
        <!-- Part enc_magnet_8 -->
        <geom class="visual" type="mesh" pos="-0.0194079 0.000122434 0.0486642" quat="0.68214 0.198428 0.678695 -0.18624" mesh="enc_magnet" material="enc_magnet_material"/>
        <!-- Part motor_support__c331c3826e3aeff78bc4513233f2bf84_4 -->
        <geom class="visual" type="mesh" pos="-0.0262199 -0.0197511 0.0488876" quat="0.24906 0.929505 -0.262743 -0.0704018" mesh="motor_support__c331c3826e3aeff78bc4513233f2bf84" material="motor_support__c331c3826e3aeff78bc4513233f2bf84_material"/>
        <!-- Part spring__c331c3826e3aeff78bc4513233f2bf84_4 -->
        <geom class="visual" type="mesh" pos="0.00162443 0.00837432 0.0389298" quat="0.00243607 0.272001 0.962255 0.00861806" mesh="spring__c331c3826e3aeff78bc4513233f2bf84" material="spring__c331c3826e3aeff78bc4513233f2bf84_material"/>
        <!-- Part spacer__c331c3826e3aeff78bc4513233f2bf84_8 -->
        <geom class="visual" type="mesh" pos="-0.0171885 -0.0253003 0.0488876" quat="0.262743 0.0704018 0.24906 0.929505" mesh="spacer__c331c3826e3aeff78bc4513233f2bf84" material="spacer__c331c3826e3aeff78bc4513233f2bf84_material"/>
        <!-- Link lfemur -->
        <body name="lfemur" pos="0.00547106 -0.0151641 0.0486642" quat="0.192341 -0.680445 0.192341 0.680445">
          <!-- Joint from lhip to lfemur -->
          <joint axis="0 0 1" name="LhipX" type="hinge" range="-1.57 1.57" frictionloss="0.01" armature="6.499e-05" damping="0.008824"/>
          <inertial pos="-0.056102 0.034471 0.00361582" mass="0.0076501" fullinertia="3.62373e-06 9.52115e-06 1.31052e-05 5.8213e-06 2.97129e-07 -1.82567e-07"/>
          <!-- Part femur -->
          <geom class="visual" type="mesh" pos="-0.0106502 0.00654388 0.0022" quat="0.872786 4.18907e-16 3.15633e-16 0.488103" mesh="femur" material="femur_material"/>
          <geom class="collision" type="mesh" pos="-0.0106502 0.00654388 0.0022" quat="0.872786 4.18907e-16 3.15633e-16 0.488103" mesh="femur" material="femur_material" name="left_femur_collision" contype="4" conaffinity="4" condim="1"/>
          <!-- Part mr63_17 -->
          <geom class="visual" type="mesh" pos="-0.0958522 0.0588949 0.0052" quat="0.962294 -1.32281e-16 2.12584e-16 -0.272012" mesh="mr63" material="mr63_material"/>
          <!-- Part mr63_18 -->
          <geom class="visual" type="mesh" pos="-0.0958522 0.0588949 0.0032" quat="0.272012 9.84621e-17 -9.49948e-17 0.962294" mesh="mr63" material="mr63_material"/>
          <!-- Part output__c331c3826e3aeff78bc4513233f2bf84_2 -->
          <geom class="visual" type="mesh" pos="0.0178642 -0.0100559 -2.30393e-19" quat="0.5 0.5 0.5 -0.5" mesh="output__c331c3826e3aeff78bc4513233f2bf84" material="output__c331c3826e3aeff78bc4513233f2bf84_material"/>
          <!-- Link tibia -->
          <body name="tibia" pos="-0.0958522 0.0588949 0.0052" quat="0.872786 0 0 0.488103">
            <!-- Joint from lfemur to tibia -->
            <joint axis="0 0 1" name="Lknee" type="hinge" range="-4.9741883682 0.7853981634" frictionloss="0.01" armature="6.499e-05" damping="0.008824"/>
            <inertial pos="0.0259177 0.0149636 0.001" mass="0.00458484" fullinertia="1.44e-06 4.27206e-06 5.70887e-06 -2.45264e-06 -0 0"/>
            <!-- Part foot -->
            <geom class="visual" type="mesh" pos="0.05 -0.0866025 0.002" quat="9.00196e-16 0.258819 -0.965926 -2.49299e-15" mesh="foot" material="foot_material"/>
            <geom class="collision" type="mesh" pos="0.05 -0.0866025 0.002" quat="9.00196e-16 0.258819 -0.965926 -2.49299e-15" mesh="foot" material="foot_material" name="left_foot_collision" contype="1" conaffinity="1" condim="3" priority="1" solref="0.002 1.0" solimp="0.998 0.9998 0.0005 0.5 2"/>
            <!-- Part collider -->
            <geom class="collision" type="mesh" pos="0.05 -0.0866025 0.002" quat="3.9412e-16 0.258819 -0.965926 -5.42003e-15" mesh="collider" material="collider_material" name="left_tibia_collision" contype="4" conaffinity="4" condim="1"/>
            <!-- Part tibia -->
            <geom class="visual" type="mesh" pos="0.05 -0.0866025 0.002" quat="1.66673e-15 0.258819 -0.965926 -1.02541e-15" mesh="tibia" material="tibia_material"/>
            <!-- Frame left_foot -->
            <site group="3" name="left_foot" pos="0.0870356 0.05025 0.001" quat="0.258819 -0 0 -0.965926"/>
            <!-- Link rod -->
            <body name="rod" pos="-0.0216506 -0.0125 0.002" quat="0 0.258819 -0.965926 -0">
              <!-- Joint from tibia to rod -->
              <joint axis="0 0 1" name="Lpassive2" type="hinge" range="-1.8325957146 3.926990817" frictionloss="0.0001" armature="1e-05" damping="0.0001" stiffness="0"/>
              <inertial pos="0.0292275 -0.0506236 -0.00392853" mass="0.0100309" fullinertia="1.55262e-05 5.40962e-06 2.03094e-05 8.76124e-06 8.27026e-07 -1.43245e-06"/>
              <!-- Part mr63_19 -->
              <geom class="visual" type="mesh" pos="-1.57999e-14 4.16334e-16 1.73125e-15" quat="5.00441e-15 -0.866025 0.5 -9.17292e-16" mesh="mr63" material="mr63_material"/>
              <!-- Part mr63_20 -->
              <geom class="visual" type="mesh" pos="-1.57999e-14 4.16334e-16 1.73125e-15" quat="0.000828389 4.1989e-15 4.28313e-15 -1" mesh="mr63" material="mr63_material"/>
              <!-- Part mr63_21 -->
              <geom class="visual" type="mesh" pos="0.05625 -0.0974279 -0.0156" quat="5.68842e-16 0.5 0.866025 4.32258e-15" mesh="mr63" material="mr63_material"/>
              <!-- Part rod -->
              <geom class="visual" type="mesh" pos="0.0716506 -0.0741025 1.05038e-15" quat="2.40513e-15 -0.258819 0.965926 2.99852e-15" mesh="rod" material="rod_material"/>
              <geom class="collision" type="mesh" pos="0.0716506 -0.0741025 1.05038e-15" quat="2.40513e-15 -0.258819 0.965926 2.99852e-15" mesh="rod" material="rod_material" name="left_rod_collision" contype="4" conaffinity="4" condim="1"/>
              <!-- Frame closing_L_2 -->
              <site group="3" name="closing_L_2" pos="0.05625 -0.0974279 -0.0176" quat="0.866025 0 0 -0.5"/>
              <!-- Frame closing_L_2_z -->
              <site group="3" name="closing_L_2_z" pos="0.05625 -0.0974279 0.0824" quat="0.866025 0 0 -0.5"/>
            </body>
          </body>
        </body>
        <!-- Link output__c331c3826e3aeff78bc4513233f2bf84 -->
        <body name="output__c331c3826e3aeff78bc4513233f2bf84" pos="-0.0175335 -0.00102929 0.0486642" quat="0.493112 0.17365 -0.685453 -0.506795">
          <!-- Joint from lhip to output__c331c3826e3aeff78bc4513233f2bf84 -->
          <joint axis="0 0 1" name="LpassiveMotor" type="hinge" range="-1.57 1.57" frictionloss="0.0001" armature="1e-05" damping="0.0001" stiffness="0"/>
          <inertial pos="-0.0072873 0.00447757 -0.0012" mass="0.00145758" fullinertia="3.8895e-08 8.3856e-08 1.21769e-07 4.4381e-08 0 0"/>
          <!-- Part output__c331c3826e3aeff78bc4513233f2bf84_3 -->
          <geom class="visual" type="mesh" pos="0.0178642 -0.0100559 -0.0024" quat="0.5 0.5 0.5 -0.5" mesh="output__c331c3826e3aeff78bc4513233f2bf84" material="output__c331c3826e3aeff78bc4513233f2bf84_material"/>
          <!-- Frame closing_L_1 -->
          <site group="3" name="closing_L_1" pos="-0.0213005 0.0130878 -0.0022" quat="0 1 0 0"/>
          <!-- Frame closing_L_1_z -->
          <site group="3" name="closing_L_1_z" pos="-0.0213005 0.0130878 -0.1022" quat="0 1 0 0"/>
        </body>
      </body>
      <!-- Link rhip -->
      <body name="rhip" pos="-0.0077 -0.0389902 0.000689504" quat="0.379928 0.596368 0.379928 0.596368">
        <!-- Joint from boddy to rhip -->
        <joint axis="0 0 1" name="RhipY" type="hinge" range="-1.57 1.57" frictionloss="0.01" armature="6.499e-05" damping="0.008824"/>
        <inertial pos="-0.00748012 -0.0096728 -0.0402115" mass="0.161992" fullinertia="4.30951e-05 7.45436e-05 6.13064e-05 -1.52592e-05 -1.1318e-05 -3.7243e-06"/>
        <!-- Part output__c331c3826e3aeff78bc4513233f2bf84_4 -->
        <geom class="visual" type="mesh" pos="0.0178642 -0.0100559 -5.81132e-17" quat="0.5 0.5 0.5 -0.5" mesh="output__c331c3826e3aeff78bc4513233f2bf84" material="output__c331c3826e3aeff78bc4513233f2bf84_material"/>
        <!-- Part kneelinkr -->
        <geom class="visual" type="mesh" pos="-0.0245159 -0.0207981 -0.0488876" quat="0.751054 0.248644 -0.444604 0.420025" mesh="kneelinkr" material="kneelinkr_material"/>
        <!-- Part gear2__c331c3826e3aeff78bc4513233f2bf84_5 -->
        <geom class="visual" type="mesh" pos="-0.0137088 0.000610972 -0.042494" quat="0.962294 -0.000377558 0.000106725 -0.272012" mesh="gear2__c331c3826e3aeff78bc4513233f2bf84" material="gear2__c331c3826e3aeff78bc4513233f2bf84_material"/>
        <!-- Part mr63_22 -->
        <geom class="visual" type="mesh" pos="-0.0188926 -0.0242533 -0.0488876" quat="0.344899 -0.345383 0.617017 -0.617288" mesh="mr63" material="mr63_material"/>
        <!-- Part spacer_small__c331c3826e3aeff78bc4513233f2bf84_13 -->
        <geom class="visual" type="mesh" pos="-0.0251989 -0.0135049 -0.0270312" quat="0.0704018 0.262743 0.929505 0.24906" mesh="spacer_small__c331c3826e3aeff78bc4513233f2bf84" material="spacer_small__c331c3826e3aeff78bc4513233f2bf84_material"/>
        <!-- Part enc_magnet_9 -->
        <geom class="visual" type="mesh" pos="-0.00628681 -0.00793963 -0.0486642" quat="0.48289 -0.692903 -0.141016 0.516543" mesh="enc_magnet" material="enc_magnet_material"/>
        <!-- Part rotor_5 -->
        <geom class="visual" type="mesh" pos="-0.0419823 -0.0100661 -0.0488876" quat="0.21229 -0.170068 -0.601649 0.751018" mesh="rotor" material="rotor_material"/>
        <!-- Part output_axis__c331c3826e3aeff78bc4513233f2bf84_5 -->
        <geom class="visual" type="mesh" pos="-0.0166196 -0.00412647 -0.06905" quat="0.441168 -0.855208 0.241742 -0.124705" mesh="output_axis__c331c3826e3aeff78bc4513233f2bf84" material="output_axis__c331c3826e3aeff78bc4513233f2bf84_material"/>
        <!-- Part mr63_23 -->
        <geom class="visual" type="mesh" pos="-0.0137846 -0.00333274 -0.0486642" quat="0.539773 -0.67176 -0.220769 0.456777" mesh="mr63" material="mr63_material"/>
        <!-- Part gear3__c331c3826e3aeff78bc4513233f2bf84_5 -->
        <geom class="visual" type="mesh" pos="-0.0166196 -0.00412647 -0.06905" quat="0.441168 -0.855208 0.241742 -0.124705" mesh="gear3__c331c3826e3aeff78bc4513233f2bf84" material="gear3__c331c3826e3aeff78bc4513233f2bf84_material"/>
        <!-- Part short_axe__c331c3826e3aeff78bc4513233f2bf84_9 -->
        <geom class="visual" type="mesh" pos="-0.0216392 -0.0122959 -0.0337321" quat="0.680178 -0.680711 0.192417 -0.192266" mesh="short_axe__c331c3826e3aeff78bc4513233f2bf84" material="short_axe__c331c3826e3aeff78bc4513233f2bf84_material"/>
        <!-- Part spacer_small__c331c3826e3aeff78bc4513233f2bf84_14 -->
        <geom class="visual" type="mesh" pos="-0.0282648 -0.0184946 -0.0488876" quat="0.0704018 0.262743 0.929505 0.24906" mesh="spacer_small__c331c3826e3aeff78bc4513233f2bf84" material="spacer_small__c331c3826e3aeff78bc4513233f2bf84_material"/>
        <!-- Part pcb_support__c331c3826e3aeff78bc4513233f2bf84_5 -->
        <geom class="visual" type="mesh" pos="-0.00986117 -0.0298025 -0.0488876" quat="0.262743 -0.0704018 -0.24906 0.929505" mesh="pcb_support__c331c3826e3aeff78bc4513233f2bf84" material="pcb_support__c331c3826e3aeff78bc4513233f2bf84_material"/>
        <!-- Part spacer_small__c331c3826e3aeff78bc4513233f2bf84_15 -->
        <geom class="visual" type="mesh" pos="-0.0397068 -0.0371167 -0.0430312" quat="0.0704018 0.262743 0.929505 0.24906" mesh="spacer_small__c331c3826e3aeff78bc4513233f2bf84" material="spacer_small__c331c3826e3aeff78bc4513233f2bf84_material"/>
        <!-- Part spacer__c331c3826e3aeff78bc4513233f2bf84_9 -->
        <geom class="visual" type="mesh" pos="-0.0255647 -0.0389326 -0.0211747" quat="0.0704018 0.262743 0.929505 0.24906" mesh="spacer__c331c3826e3aeff78bc4513233f2bf84" material="spacer__c331c3826e3aeff78bc4513233f2bf84_material"/>
        <!-- Part stator_5 -->
        <geom class="visual" type="mesh" pos="-0.0419823 -0.0100661 -0.0488876" quat="0.262743 -0.0704018 -0.24906 0.929505" mesh="stator" material="stator_material"/>
        <!-- Part output_support__c331c3826e3aeff78bc4513233f2bf84_5 -->
        <geom class="visual" type="mesh" pos="-0.0320137 -0.0161912 -0.0488876" quat="0.262743 -0.0704018 -0.24906 0.929505" mesh="output_support__c331c3826e3aeff78bc4513233f2bf84" material="output_support__c331c3826e3aeff78bc4513233f2bf84_material"/>
        <!-- Part gear1__c331c3826e3aeff78bc4513233f2bf84_5 -->
        <geom class="visual" type="mesh" pos="-0.019915 -0.023625 -0.0488876" quat="0.192417 -0.192266 -0.680178 0.680711" mesh="gear1__c331c3826e3aeff78bc4513233f2bf84" material="gear1__c331c3826e3aeff78bc4513233f2bf84_material"/>
        <!-- Part mr63_24 -->
        <geom class="visual" type="mesh" pos="-0.0192375 1.77317e-05 -0.0486642" quat="0.177508 -0.490249 0.509564 -0.684464" mesh="mr63" material="mr63_material"/>
        <!-- Part short_axe__c331c3826e3aeff78bc4513233f2bf84_10 -->
        <geom class="visual" type="mesh" pos="-0.0171885 -0.0253003 -0.0488876" quat="0.192417 -0.192266 -0.680178 0.680711" mesh="short_axe__c331c3826e3aeff78bc4513233f2bf84" material="short_axe__c331c3826e3aeff78bc4513233f2bf84_material"/>
        <!-- Part mr63_25 -->
        <geom class="visual" type="mesh" pos="-0.00816125 -0.00678791 -0.0486642" quat="0.503946 -0.1588 0.689045 -0.496023" mesh="mr63" material="mr63_material"/>
        <!-- Part enc_magnet_10 -->
        <geom class="visual" type="mesh" pos="-0.0194079 0.000122434 -0.0486642" quat="0.141016 -0.516543 0.48289 -0.692903" mesh="enc_magnet" material="enc_magnet_material"/>
        <!-- Part motor_support__c331c3826e3aeff78bc4513233f2bf84_5 -->
        <geom class="visual" type="mesh" pos="-0.0245159 -0.0207981 -0.0488876" quat="0.262743 -0.0704018 -0.24906 0.929505" mesh="motor_support__c331c3826e3aeff78bc4513233f2bf84" material="motor_support__c331c3826e3aeff78bc4513233f2bf84_material"/>
        <!-- Part spring__c331c3826e3aeff78bc4513233f2bf84_5 -->
        <geom class="visual" type="mesh" pos="-0.0175311 -0.0228015 -0.0573924" quat="0.241742 -0.124705 -0.441168 0.855208" mesh="spring__c331c3826e3aeff78bc4513233f2bf84" material="spring__c331c3826e3aeff78bc4513233f2bf84_material"/>
        <!-- Part spacer__c331c3826e3aeff78bc4513233f2bf84_10 -->
        <geom class="visual" type="mesh" pos="-0.0171885 -0.0253003 -0.0488876" quat="0.0704018 0.262743 0.929505 0.24906" mesh="spacer__c331c3826e3aeff78bc4513233f2bf84" material="spacer__c331c3826e3aeff78bc4513233f2bf84_material"/>
        <!-- Part gear2__c331c3826e3aeff78bc4513233f2bf84_6 -->
        <geom class="visual" type="mesh" pos="0.0206457 0.0141173 -0.0355718" quat="0.0151729 0.271588 0.960796 0.0536771" mesh="gear2__c331c3826e3aeff78bc4513233f2bf84" material="gear2__c331c3826e3aeff78bc4513233f2bf84_material"/>
        <!-- Part mr63_26 -->
        <geom class="visual" type="mesh" pos="0.00136323 -0.000837617 -0.0308" quat="0.345141 0.345141 -0.617153 -0.617153" mesh="mr63" material="mr63_material"/>
        <!-- Part spacer_small__c331c3826e3aeff78bc4513233f2bf84_16 -->
        <geom class="visual" type="mesh" pos="0.0191116 0.00703607 -0.0148" quat="0.680445 0.680445 -0.192341 -0.192341" mesh="spacer_small__c331c3826e3aeff78bc4513233f2bf84" material="spacer_small__c331c3826e3aeff78bc4513233f2bf84_material"/>
        <!-- Part enc_magnet_11 -->
        <geom class="visual" type="mesh" pos="-0.00577559 -0.00825374 -0.0486642" quat="0.237412 -0.443208 0.550969 -0.66606" mesh="enc_magnet" material="enc_magnet_material"/>
        <!-- Part rotor_6 -->
        <geom class="visual" type="mesh" pos="0.024453 -0.0150248 -0.0308" quat="0.64143 0.717341 -0.202771 -0.181313" mesh="rotor" material="rotor_material"/>
        <!-- Part output_axis__c331c3826e3aeff78bc4513233f2bf84_6 -->
        <geom class="visual" type="mesh" pos="-0.00462038 -0.0270036 -0.0622288" quat="0.221718 -0.15758 -0.557469 0.784371" mesh="output_axis__c331c3826e3aeff78bc4513233f2bf84" material="output_axis__c331c3826e3aeff78bc4513233f2bf84_material"/>
        <!-- Part mr63_27 -->
        <geom class="visual" type="mesh" pos="0.00172217 -0.0128606 -0.0486642" quat="0.617153 0.617153 0.345141 0.345141" mesh="mr63" material="mr63_material"/>
        <!-- Part gear3__c331c3826e3aeff78bc4513233f2bf84_6 -->
        <geom class="visual" type="mesh" pos="-0.00462038 -0.0270036 -0.0622288" quat="0.221718 -0.15758 -0.557469 0.784371" mesh="gear3__c331c3826e3aeff78bc4513233f2bf84" material="gear3__c331c3826e3aeff78bc4513233f2bf84_material"/>
        <!-- Part short_axe__c331c3826e3aeff78bc4513233f2bf84_11 -->
        <geom class="visual" type="mesh" pos="0.0132713 0.00211536 -0.0459554" quat="0.192341 0.192341 0.680445 0.680445" mesh="short_axe__c331c3826e3aeff78bc4513233f2bf84" material="short_axe__c331c3826e3aeff78bc4513233f2bf84_material"/>
        <!-- Part spacer_small__c331c3826e3aeff78bc4513233f2bf84_17 -->
        <geom class="visual" type="mesh" pos="0.0107354 -0.00659623 -0.0308" quat="0.680445 0.680445 -0.192341 -0.192341" mesh="spacer_small__c331c3826e3aeff78bc4513233f2bf84" material="spacer_small__c331c3826e3aeff78bc4513233f2bf84_material"/>
        <!-- Part pcb_support__c331c3826e3aeff78bc4513233f2bf84_6 -->
        <geom class="visual" type="mesh" pos="0.0086906 -0.00533981 -0.0308" quat="0.192341 0.192341 0.680445 0.680445" mesh="pcb_support__c331c3826e3aeff78bc4513233f2bf84" material="pcb_support__c331c3826e3aeff78bc4513233f2bf84_material"/>
        <!-- Part spacer_small__c331c3826e3aeff78bc4513233f2bf84_18 -->
        <geom class="visual" type="mesh" pos="0.0191116 0.00703607 -0.0468" quat="0.680445 0.680445 -0.192341 -0.192341" mesh="spacer_small__c331c3826e3aeff78bc4513233f2bf84" material="spacer_small__c331c3826e3aeff78bc4513233f2bf84_material"/>
        <!-- Part spacer__c331c3826e3aeff78bc4513233f2bf84_11 -->
        <geom class="visual" type="mesh" pos="0.0164115 0.027474 -0.0308" quat="0.680445 0.680445 -0.192341 -0.192341" mesh="spacer__c331c3826e3aeff78bc4513233f2bf84" material="spacer__c331c3826e3aeff78bc4513233f2bf84_material"/>
        <!-- Part stator_6 -->
        <geom class="visual" type="mesh" pos="0.024453 -0.0150248 -0.0308" quat="0.680445 -0.680445 0.192341 -0.192341" mesh="stator" material="stator_material"/>
        <!-- Part output_support__c331c3826e3aeff78bc4513233f2bf84_6 -->
        <geom class="visual" type="mesh" pos="0.0086906 -0.00533981 -0.0308" quat="0.192341 0.192341 0.680445 0.680445" mesh="output_support__c331c3826e3aeff78bc4513233f2bf84" material="output_support__c331c3826e3aeff78bc4513233f2bf84_material"/>
        <!-- Part gear1__c331c3826e3aeff78bc4513233f2bf84_6 -->
        <geom class="visual" type="mesh" pos="0.00238565 -0.00146583 -0.0308" quat="0.64143 0.717341 -0.202771 -0.181313" mesh="gear1__c331c3826e3aeff78bc4513233f2bf84" material="gear1__c331c3826e3aeff78bc4513233f2bf84_material"/>
        <!-- Part mr63_28 -->
        <geom class="visual" type="mesh" pos="0.0071751 -0.0162111 -0.0486642" quat="0.345141 0.345141 -0.617153 -0.617153" mesh="mr63" material="mr63_material"/>
        <!-- Part short_axe__c331c3826e3aeff78bc4513233f2bf84_12 -->
        <geom class="visual" type="mesh" pos="-0.000340808 0.000209404 -0.0308" quat="0.641562 0.717222 -0.202737 -0.181351" mesh="short_axe__c331c3826e3aeff78bc4513233f2bf84" material="short_axe__c331c3826e3aeff78bc4513233f2bf84_material"/>
        <!-- Part mr63_29 -->
        <geom class="visual" type="mesh" pos="-0.00390115 -0.00940546 -0.0486642" quat="0.345141 0.345141 -0.617153 -0.617153" mesh="mr63" material="mr63_material"/>
        <!-- Part enc_magnet_12 -->
        <geom class="visual" type="mesh" pos="0.0073455 -0.0163158 -0.0486642" quat="0.550969 -0.66606 -0.237412 0.443208" mesh="enc_magnet" material="enc_magnet_material"/>
        <!-- Part motor_support__c331c3826e3aeff78bc4513233f2bf84_6 -->
        <geom class="visual" type="mesh" pos="0.0086906 -0.00533981 -0.0308" quat="0.192341 0.192341 0.680445 0.680445" mesh="motor_support__c331c3826e3aeff78bc4513233f2bf84" material="motor_support__c331c3826e3aeff78bc4513233f2bf84_material"/>
        <!-- Part spring__c331c3826e3aeff78bc4513233f2bf84_6 -->
        <geom class="visual" type="mesh" pos="-0.00234517 -0.00610901 -0.0688414" quat="0.557469 -0.784371 0.221718 -0.15758" mesh="spring__c331c3826e3aeff78bc4513233f2bf84" material="spring__c331c3826e3aeff78bc4513233f2bf84_material"/>
        <!-- Part spacer__c331c3826e3aeff78bc4513233f2bf84_12 -->
        <geom class="visual" type="mesh" pos="-0.000340808 0.000209404 -0.0308" quat="0.680445 0.680445 -0.192341 -0.192341" mesh="spacer__c331c3826e3aeff78bc4513233f2bf84" material="spacer__c331c3826e3aeff78bc4513233f2bf84_material"/>
        <!-- Link rfemur -->
        <body name="rfemur" pos="0.00547106 -0.0151641 -0.0486642" quat="0.192341 0.680445 -0.192341 0.680445">
          <!-- Joint from rhip to rfemur -->
          <joint axis="0 0 1" name="RhipX" type="hinge" range="-1.57 1.57" frictionloss="0.01" armature="6.499e-05" damping="0.008824"/>
          <inertial pos="-0.056102 0.034471 -0.00361582" mass="0.0076501" fullinertia="3.62373e-06 9.52115e-06 1.31052e-05 5.8213e-06 -2.97129e-07 1.82567e-07"/>
          <!-- Part femur_2 -->
          <geom class="visual" type="mesh" pos="-0.0106502 0.00654388 -0.0022" quat="1.585e-16 -0.488103 0.872786 6.47839e-15" mesh="femur" material="femur_material"/>
          <geom class="collision" type="mesh" pos="-0.0106502 0.00654388 -0.0022" quat="1.585e-16 -0.488103 0.872786 6.47839e-15" mesh="femur" material="femur_material" name="right_femur_collision" contype="4" conaffinity="4" condim="1"/>
          <!-- Part mr63_30 -->
          <geom class="visual" type="mesh" pos="-0.0958522 0.0588949 -0.0052" quat="5.25395e-16 0.962294 -0.272012 4.32039e-16" mesh="mr63" material="mr63_material"/>
          <!-- Part mr63_31 -->
          <geom class="visual" type="mesh" pos="-0.0958522 0.0588949 -0.0032" quat="1.24133e-15 -0.272012 -0.962294 2.38312e-15" mesh="mr63" material="mr63_material"/>
          <!-- Part output__c331c3826e3aeff78bc4513233f2bf84_5 -->
          <geom class="visual" type="mesh" pos="0.0178642 -0.0100559 -0.0024" quat="0.5 0.5 0.5 -0.5" mesh="output__c331c3826e3aeff78bc4513233f2bf84" material="output__c331c3826e3aeff78bc4513233f2bf84_material"/>
          <!-- Link tibia_2 -->
          <body name="tibia_2" pos="-0.0958522 0.0588949 -0.0052" quat="0.488103 0 0 -0.872786">
            <!-- Joint from rfemur to tibia_2 -->
            <joint axis="0 0 1" name="Rknee" type="hinge" range="-4.9741883682 0.7853981634" frictionloss="0.01" armature="6.499e-05" damping="0.008824"/>
            <inertial pos="-0.0259177 -0.0149636 -0.001" mass="0.00458484" fullinertia="1.44e-06 4.27206e-06 5.70887e-06 -2.45264e-06 -0 0"/>
            <!-- Part collider_2 -->
            <geom class="collision" type="mesh" pos="0.05 -0.0866025 -0.002" quat="0.965926 3.79318e-15 -6.96302e-15 0.258819" mesh="collider" material="collider_material" name="right_tibia_collision" contype="4" conaffinity="4" condim="1"/>
            <!-- Part tibia_2 -->
            <geom class="visual" type="mesh" pos="0.05 -0.0866025 -0.002" quat="0.965926 4.14165e-15 -6.80498e-15 0.258819" mesh="tibia" material="tibia_material"/>
            <!-- Part foot_2 -->
            <geom class="visual" type="mesh" pos="-0.05 0.0866025 -1.68962e-15" quat="3.99949e-15 -0.965926 -0.258819 -6.82993e-15" mesh="foot" material="foot_material"/>
            <geom class="collision" type="mesh" pos="-0.05 0.0866025 -1.68962e-15" quat="3.99949e-15 -0.965926 -0.258819 -6.82993e-15" mesh="foot" material="foot_material" name="right_foot_collision" contype="1" conaffinity="1" condim="3" priority="1" solref="0.002 1.0" solimp="0.998 0.9998 0.0005 0.5 2"/>
            <!-- Frame right_foot -->
            <site group="3" name="right_foot" pos="-0.0870356 -0.05025 -0.001" quat="0 -0.965926 -0.258819 -0"/>
            <!-- Link rod_2 -->
            <body name="rod_2" pos="0.0216506 0.0125 -0.002" quat="0 -0.965926 -0.258819 -0">
              <!-- Joint from tibia_2 to rod_2 -->
              <joint axis="0 0 1" name="Rpassive2" type="hinge" range="-1.8325957146 3.926990817" frictionloss="0.0001" armature="1e-05" damping="0.0001" stiffness="0"/>
              <inertial pos="0.0292275 -0.0506236 0.00392853" mass="0.0100309" fullinertia="1.55262e-05 5.40962e-06 2.03094e-05 8.76124e-06 -8.27026e-07 1.43245e-06"/>
              <!-- Part mr63_32 -->
              <geom class="visual" type="mesh" pos="0 -2.77556e-17 -4.33681e-18" quat="0.866025 -1.74096e-16 -2.97459e-16 -0.5" mesh="mr63" material="mr63_material"/>
              <!-- Part mr63_33 -->
              <geom class="visual" type="mesh" pos="0 -2.77556e-17 -4.33681e-18" quat="3.37446e-16 0.812749 0.582613 -1.70772e-16" mesh="mr63" material="mr63_material"/>
              <!-- Part mr63_34 -->
              <geom class="visual" type="mesh" pos="0.05625 -0.0974279 0.0156" quat="0.5 -2.30611e-16 5.17964e-16 0.866025" mesh="mr63" material="mr63_material"/>
              <!-- Part rod_2 -->
              <geom class="visual" type="mesh" pos="0.0283494 -0.0991025 7.54605e-17" quat="0.965926 -1.86403e-16 1.95275e-16 0.258819" mesh="rod" material="rod_material"/>
              <geom class="collision" type="mesh" pos="0.0283494 -0.0991025 7.54605e-17" quat="0.965926 -1.86403e-16 1.95275e-16 0.258819" mesh="rod" material="rod_material" name="right_rod_collision" contype="4" conaffinity="4" condim="1"/>
              <!-- Frame closing_R_2 -->
              <site group="3" name="closing_R_2" pos="0.05625 -0.0974279 0.0176" quat="0 0.866025 -0.5 0"/>
              <!-- Frame closing_R_2_z -->
              <site group="3" name="closing_R_2_z" pos="0.05625 -0.0974279 -0.0824" quat="0 0.866025 -0.5 0"/>
            </body>
          </body>
        </body>
        <!-- Link output__c331c3826e3aeff78bc4513233f2bf84_2 -->
        <body name="output__c331c3826e3aeff78bc4513233f2bf84_2" pos="-0.0175335 -0.00102929 -0.0486642" quat="0.493112 -0.17365 0.685453 -0.506795">
          <!-- Joint from rhip to output__c331c3826e3aeff78bc4513233f2bf84_2 -->
          <joint axis="0 0 1" name="RpassiveMotor" type="hinge" range="-1.57 1.57" frictionloss="0.0001" armature="1e-05" damping="0.0001" stiffness="0"/>
          <inertial pos="-0.0072873 0.00447757 0.0012" mass="0.00145758" fullinertia="3.8895e-08 8.3856e-08 1.21769e-07 4.4381e-08 0 0"/>
          <!-- Part output__c331c3826e3aeff78bc4513233f2bf84_6 -->
          <geom class="visual" type="mesh" pos="0.0178642 -0.0100559 -8.67362e-19" quat="0.5 0.5 0.5 -0.5" mesh="output__c331c3826e3aeff78bc4513233f2bf84" material="output__c331c3826e3aeff78bc4513233f2bf84_material"/>
          <!-- Frame closing_R_1 -->
          <site group="3" name="closing_R_1" pos="-0.0213005 0.0130878 0.0022" quat="1 0 -0 -0"/>
          <!-- Frame closing_R_1_z -->
          <site group="3" name="closing_R_1_z" pos="-0.0213005 0.0130878 0.1022" quat="1 0 -0 -0"/>
        </body>
      </body>
    </body>
  </worldbody>
  <asset>
    <mesh file="antenna.stl"/>
    <mesh file="pcb_support__c331c3826e3aeff78bc4513233f2bf84.stl"/>
    <mesh file="spacer__c331c3826e3aeff78bc4513233f2bf84.stl"/>
    <mesh file="brd.stl"/>
    <mesh file="kneelinkl.stl"/>
    <mesh file="output_support__c331c3826e3aeff78bc4513233f2bf84.stl"/>
    <mesh file="rod.stl"/>
    <mesh file="short_axe__c331c3826e3aeff78bc4513233f2bf84.stl"/>
    <mesh file="femur.stl"/>
    <mesh file="output_axis__c331c3826e3aeff78bc4513233f2bf84.stl"/>
    <mesh file="stator.stl"/>
    <mesh file="spacer_small__c331c3826e3aeff78bc4513233f2bf84.stl"/>
    <mesh file="tibia.stl"/>
    <mesh file="kneelinkr.stl"/>
    <mesh file="trunclink.stl"/>
    <mesh file="foot.stl"/>
    <mesh file="motor_support__c331c3826e3aeff78bc4513233f2bf84.stl"/>
    <mesh file="gear1__c331c3826e3aeff78bc4513233f2bf84.stl"/>
    <mesh file="spring__c331c3826e3aeff78bc4513233f2bf84.stl"/>
    <mesh file="enc_magnet.stl"/>
    <mesh file="mr63.stl"/>
    <mesh file="output__c331c3826e3aeff78bc4513233f2bf84.stl"/>
    <mesh file="rotor.stl"/>
    <mesh file="collider.stl"/>
    <mesh file="gear2__c331c3826e3aeff78bc4513233f2bf84.stl"/>
    <mesh file="gear3__c331c3826e3aeff78bc4513233f2bf84.stl"/>
    <material name="trunclink_material" rgba="0.615686 0.811765 0.929412 1"/>
    <material name="antenna_material" rgba="0.498039 0.498039 0.498039 1"/>
    <material name="brd_material" rgba="0.972549 0.529412 0.00392157 1"/>
    <material name="gear2__c331c3826e3aeff78bc4513233f2bf84_material" rgba="0.647059 0.647059 0.647059 1"/>
    <material name="mr63_material" rgba="0.615686 0.811765 0.929412 1"/>
    <material name="spacer_small__c331c3826e3aeff78bc4513233f2bf84_material" rgba="0.917647 0.917647 0.917647 1"/>
    <material name="enc_magnet_material" rgba="0.615686 0.811765 0.929412 1"/>
    <material name="rotor_material" rgba="0.647059 0.647059 0.647059 1"/>
    <material name="output_axis__c331c3826e3aeff78bc4513233f2bf84_material" rgba="0.615686 0.811765 0.929412 1"/>
    <material name="gear3__c331c3826e3aeff78bc4513233f2bf84_material" rgba="0.917647 0.917647 0.917647 1"/>
    <material name="short_axe__c331c3826e3aeff78bc4513233f2bf84_material" rgba="0.768627 0.886275 0.952941 1"/>
    <material name="pcb_support__c331c3826e3aeff78bc4513233f2bf84_material" rgba="0.498039 0.498039 0.498039 1"/>
    <material name="spacer__c331c3826e3aeff78bc4513233f2bf84_material" rgba="0.972549 0.529412 0.00392157 1"/>
    <material name="stator_material" rgba="0.615686 0.811765 0.929412 1"/>
    <material name="output_support__c331c3826e3aeff78bc4513233f2bf84_material" rgba="0.231373 0.380392 0.705882 1"/>
    <material name="gear1__c331c3826e3aeff78bc4513233f2bf84_material" rgba="0.231373 0.380392 0.705882 1"/>
    <material name="motor_support__c331c3826e3aeff78bc4513233f2bf84_material" rgba="0.615686 0.811765 0.929412 1"/>
    <material name="spring__c331c3826e3aeff78bc4513233f2bf84_material" rgba="0.980392 0.713725 0.00392157 1"/>
    <material name="output__c331c3826e3aeff78bc4513233f2bf84_material" rgba="0.647059 0.647059 0.647059 1"/>
    <material name="kneelinkl_material" rgba="0.647059 0.647059 0.647059 1"/>
    <material name="femur_material" rgba="0.231373 0.380392 0.705882 1"/>
    <material name="foot_material" rgba="0.980392 0.713725 0.00392157 1"/>
    <material name="collider_material" rgba="0.647059 0.647059 0.647059 1"/>
    <material name="tibia_material" rgba="0.917647 0.917647 0.917647 1"/>
    <material name="rod_material" rgba="0.768627 0.886275 0.952941 1"/>
    <material name="kneelinkr_material" rgba="0.647059 0.647059 0.647059 1"/>
  </asset>
  <actuator>
    <position class="leggy" name="LhipY" joint="LhipY" kp="10" forcerange="-0.236 0.236" inheritrange="1"/>
    <position class="leggy" name="LhipX" joint="LhipX" kp="10" forcerange="-0.236 0.236" inheritrange="1"/>
    <position class="leggy" name="Lknee" joint="Lknee" kp="10" forcerange="-0.236 0.236" inheritrange="1"/>
    <position class="leggy" name="RhipY" joint="RhipY" kp="10" forcerange="-0.236 0.236" inheritrange="1"/>
    <position class="leggy" name="RhipX" joint="RhipX" kp="10" forcerange="-0.236 0.236" inheritrange="1"/>
    <position class="leggy" name="Rknee" joint="Rknee" kp="10" forcerange="-0.236 0.236" inheritrange="1"/>
  </actuator>
  <equality>
    <connect site1="closing_L_1" site2="closing_L_2" solref="0.002 1" solimp="0.99 0.999 0.0005 0.5 2"/>
    <connect site1="closing_L_1_z" site2="closing_L_2_z" solref="0.002 1" solimp="0.99 0.999 0.0005 0.5 2"/>
    <connect site1="closing_R_1" site2="closing_R_2" solref="0.002 1" solimp="0.99 0.999 0.0005 0.5 2"/>
    <connect site1="closing_R_1_z" site2="closing_R_2_z" solref="0.002 1" solimp="0.99 0.999 0.0005 0.5 2"/>
  </equality>
</mujoco>
